Workbook

Sheet Curves
A1: Node index | B1: 1 | C1: 2 | D1: 3 | E1: 4 | F1: 5 | G1: 6
A2: Node t (days) | B2: 1 | C2: 30 | D2: 90 | E2: 180 | F2: 365 | G2: 730
A3: Notional curve rate | B3: 0.01 | C3: 0.015 | D3: 0.02 | E3: 0.025 | F3: 0.03 | G3: 0.035
A4: Settlement/discount curve rate | B4: 0.02 | C4: 0.025 | D4: 0.03 | E4: 0.035 | F4: 0.04 | G4: 0.045
A6: Spot FX (USDCLP) | B6: 900
A7: Nominal (USD) | B7: 1000000
A8: t_floating (days to end date) | B8: 366
A9: t_fixed (days to end date) | B9: 183
A10: Historical FX fixing | B10: 875
A12: Interpolation: linear on the rate between bracketing nodes (QCLinearInterpolator). wf(t) = 1 + rate(t) * t/360 (QCAct360 + QCLinearWf). DF(t) = 1/wf(t). Matches ZeroCouponCurve::getDiscountFactorAt exactly.

Sheet FixedRate
A1: FixedRateMultiCurrencyCashflow
A2: qcfinancial results (Python, live — see settlement_currency_review.py)
B3: Step | C3: Amount / PV (CLP) | D3: Notes
A4: Spot fixing (historical FX = 875.0) | B4: 875000000 | D4: settlement_amount() after ForwardFXRates.set_fx_rate
A5: CIP forward, still floating | B5: 8.7335064e+08 | D5: PresentValueFX.pv; FX delta = 970,389.6026
A6: CIP forward, already fixed | B6: 8.5966961e+08 | D6: PresentValueFX.pv; all curve/spot derivatives are 0 once fixed
A8: Floating-case curve-vertex derivatives at node 5 (t=365d):
A9: notional-curve | B9: -8.5925463e+08
A10: CIP-settlement-curve | B10: 8.5086036e+08
A11: discount-curve | B11: -8.5086036e+08
A16: Node t (days) | B16: =Curves!B2 -> 1 | C16: =Curves!C2 -> 30 | D16: =Curves!D2 -> 90 | E16: =Curves!E2 -> 180 | F16: =Curves!F2 -> 365 | G16: =Curves!G2 -> 730
A17: Notional curve rate | B17: =Curves!B3 -> 0.01 | C17: =Curves!C3 -> 0.015 | D17: =Curves!D3 -> 0.02 | E17: =Curves!E3 -> 0.025 | F17: =Curves!F3 -> 0.03 | G17: =Curves!G3 -> 0.035
A18: Settlement/discount curve rate | B18: =Curves!B4 -> 0.02 | C18: =Curves!C4 -> 0.025 | D18: =Curves!D4 -> 0.03 | E18: =Curves!E4 -> 0.035 | F18: =Curves!F4 -> 0.04 | G18: =Curves!G4 -> 0.045
A20: Spot | B20: =Curves!B6 -> 900
A21: Nominal (notional-currency amount(); zero-rate construction, see notebook) | B21: =Curves!B7 -> 1000000
A22: t_floating | B22: =Curves!B8 -> 366
A23: t_fixed | B23: =Curves!B9 -> 183
A24: Historical FX fixing | B24: =Curves!B10 -> 875
A26: CIP forward projection (still floating)
A27: idx (largest node <= t_floating) | B27: =MATCH(B22,Curves!$B$2:$G$2,1) -> 5
A28: x1, x2 (bracketing node t's) | B28: =INDEX(Curves!$B$2:$G$2,B27) -> 365 | C28: =IF(B27=6,B28,INDEX(Curves!$B$2:$G$2,B27+1)) -> 730
A29: frac = (t_floating - x1) / (x2 - x1) | B29: =IF(B27=6,0,(B22-B28)/(C28-B28)) -> 0.002739726
A30: Interpolated notional-curve rate at t_floating | B30: =INDEX(Curves!$B$3:$G$3,B27)+(INDEX(Curves!$B$3:$G$3,B27+1-IF(B27=6,1,0))-INDEX(Curves!$B$3:$G$3,B27))*B29 -> 0.030013699
A31: Interpolated settlement-curve rate at t_floating | B31: =INDEX(Curves!$B$4:$G$4,B27)+(INDEX(Curves!$B$4:$G$4,B27+1-IF(B27=6,1,0))-INDEX(Curves!$B$4:$G$4,B27))*B29 -> 0.040013699
A32: wf_notional = 1 + rate * t_floating/360 | B32: =1+B30*B22/360 -> 1.0305139
A33: wf_settlement = 1 + rate * t_floating/360 | B33: =1+B31*B22/360 -> 1.0406806
A34: DF_notional(t_floating) = 1/wf_notional | B34: =1/B32 -> 0.9703896
A35: DF_settlement(t_floating) = 1/wf_settlement | B35: =1/B33 -> 0.96090963
A36: Forward = Spot * DF_notional / DF_settlement | B36: =B20*B34/B35 -> 908.87906
A37: Amount (settlement ccy, strong-side notional) = Nominal * Forward | B37: =B21*B36 -> 9.0887906e+08
A38: PV (floating) = Amount * DF_settlement [discount curve = settlement curve here] | B38: =B37*B35 -> 8.7335064e+08
A39: dForward/dSpot = DF_notional/DF_settlement | B39: =B34/B35 -> 1.0098656
A40: FX delta = Nominal * dForward/dSpot * DF_settlement | B40: =B21*B39*B35 -> 970389.6
A42: Per-node curve-vertex derivatives (floating case)
A43: dRate/dNode_j (shared: same node grid for both curves) | B43: =IF(B16=B28,1-B29,IF(B16=C28,B29,0)) -> 0 | C43: =IF(C16=B28,1-B29,IF(C16=C28,B29,0)) -> 0 | D43: =IF(D16=B28,1-B29,IF(D16=C28,B29,0)) -> 0 | E43: =IF(E16=B28,1-B29,IF(E16=C28,B29,0)) -> 0 | F43: =IF(F16=B28,1-B29,IF(F16=C28,B29,0)) -> 0.99726027 | G43: =IF(G16=B28,1-B29,IF(G16=C28,B29,0)) -> 0.002739726
A44: dDF_notional/dNode_j = -(t_floating/360) * dRate/dNode_j / wf_notional^2 | B44: =-(B22/360)*B43/(B32^2) -> 0 | C44: =-(B22/360)*C43/(B32^2) -> 0 | D44: =-(B22/360)*D43/(B32^2) -> 0 | E44: =-(B22/360)*E43/(B32^2) -> 0 | F44: =-(B22/360)*F43/(B32^2) -> -0.95472737 | G44: =-(B22/360)*G43/(B32^2) -> -0.0026228774
A45: dDF_settlement/dNode_j = -(t_floating/360) * dRate/dNode_j / wf_settlement^2 | B45: =-(B22/360)*B43/(B33^2) -> 0 | C45: =-(B22/360)*C43/(B33^2) -> 0 | D45: =-(B22/360)*D43/(B33^2) -> 0 | E45: =-(B22/360)*E43/(B33^2) -> 0 | F45: =-(B22/360)*F43/(B33^2) -> -0.93616455 | G45: =-(B22/360)*G43/(B33^2) -> -0.0025718806
A46: dPV/dNotionalNode_j = Nominal * Spot * dDF_notional/dNode_j / DF_settlement * DF_settlement | B46: =B21*B20*B44/B35*B35 -> 0 | C46: =B21*B20*C44/B35*B35 -> 0 | D46: =B21*B20*D44/B35*B35 -> 0 | E46: =B21*B20*E44/B35*B35 -> 0 | F46: =B21*B20*F44/B35*B35 -> -8.5925463e+08 | G46: =B21*B20*G44/B35*B35 -> -2360589.7
A47: dPV/dCipSettlementNode_j = Nominal * (-Spot*DF_notional/DF_settlement^2) * dDF_settlement/dNode_j * DF_settlement | B47: =B21*(-B20*B34/(B35^2))*B45*B35 -> 0 | C47: =B21*(-B20*B34/(B35^2))*C45*B35 -> 0 | D47: =B21*(-B20*B34/(B35^2))*D45*B35 -> 0 | E47: =B21*(-B20*B34/(B35^2))*E45*B35 -> 0 | F47: =B21*(-B20*B34/(B35^2))*F45*B35 -> 8.5086036e+08 | G47: =B21*(-B20*B34/(B35^2))*G45*B35 -> 2337528.5
A48: dPV/dDiscountNode_j = Amount * dDF_settlement/dNode_j [discount curve = settlement curve] | B48: =B37*B45 -> 0 | C48: =B37*C45 -> 0 | D48: =B37*D45 -> 0 | E48: =B37*E45 -> 0 | F48: =B37*F45 -> -8.5086036e+08 | G48: =B37*G45 -> -2337528.5
...

Sheet Ibor
A1: IborMultiCurrencyCashflow
A2: qcfinancial results (Python, live — see settlement_currency_review.py)
B3: Step | C3: Amount / PV (CLP) | D3: Notes
A4: Spot fixing (historical FX = 875.0) | B4: 1000000 | D4: settlement_amount() after ForwardFXRates.set_fx_rate
A5: CIP forward, still floating | B5: 8.7335064e+08 | D5: PresentValueFX.pv; FX delta = 970,389.6026
A6: CIP forward, already fixed | B6: 8.5966961e+08 | D6: PresentValueFX.pv; all curve/spot derivatives are 0 once fixed
A8: Floating-case curve-vertex derivatives at node 5 (t=365d):
A9: notional-curve | B9: -8.5925463e+08
A10: CIP-settlement-curve | B10: 8.5086036e+08
A11: discount-curve | B11: -8.5086036e+08
A16: Node t (days) | B16: =Curves!B2 -> 1 | C16: =Curves!C2 -> 30 | D16: =Curves!D2 -> 90 | E16: =Curves!E2 -> 180 | F16: =Curves!F2 -> 365 | G16: =Curves!G2 -> 730
A17: Notional curve rate | B17: =Curves!B3 -> 0.01 | C17: =Curves!C3 -> 0.015 | D17: =Curves!D3 -> 0.02 | E17: =Curves!E3 -> 0.025 | F17: =Curves!F3 -> 0.03 | G17: =Curves!G3 -> 0.035
A18: Settlement/discount curve rate | B18: =Curves!B4 -> 0.02 | C18: =Curves!C4 -> 0.025 | D18: =Curves!D4 -> 0.03 | E18: =Curves!E4 -> 0.035 | F18: =Curves!F4 -> 0.04 | G18: =Curves!G4 -> 0.045
A20: Spot | B20: =Curves!B6 -> 900
A21: Nominal (notional-currency amount(); zero-rate construction, see notebook) | B21: =Curves!B7 -> 1000000
A22: t_floating | B22: =Curves!B8 -> 366
A23: t_fixed | B23: =Curves!B9 -> 183
A24: Historical FX fixing | B24: =Curves!B10 -> 875
A26: CIP forward projection (still floating)
A27: idx (largest node <= t_floating) | B27: =MATCH(B22,Curves!$B$2:$G$2,1) -> 5
A28: x1, x2 (bracketing node t's) | B28: =INDEX(Curves!$B$2:$G$2,B27) -> 365 | C28: =IF(B27=6,B28,INDEX(Curves!$B$2:$G$2,B27+1)) -> 730
A29: frac = (t_floating - x1) / (x2 - x1) | B29: =IF(B27=6,0,(B22-B28)/(C28-B28)) -> 0.002739726
A30: Interpolated notional-curve rate at t_floating | B30: =INDEX(Curves!$B$3:$G$3,B27)+(INDEX(Curves!$B$3:$G$3,B27+1-IF(B27=6,1,0))-INDEX(Curves!$B$3:$G$3,B27))*B29 -> 0.030013699
A31: Interpolated settlement-curve rate at t_floating | B31: =INDEX(Curves!$B$4:$G$4,B27)+(INDEX(Curves!$B$4:$G$4,B27+1-IF(B27=6,1,0))-INDEX(Curves!$B$4:$G$4,B27))*B29 -> 0.040013699
A32: wf_notional = 1 + rate * t_floating/360 | B32: =1+B30*B22/360 -> 1.0305139
A33: wf_settlement = 1 + rate * t_floating/360 | B33: =1+B31*B22/360 -> 1.0406806
A34: DF_notional(t_floating) = 1/wf_notional | B34: =1/B32 -> 0.9703896
A35: DF_settlement(t_floating) = 1/wf_settlement | B35: =1/B33 -> 0.96090963
A36: Forward = Spot * DF_notional / DF_settlement | B36: =B20*B34/B35 -> 908.87906
A37: Amount (settlement ccy, strong-side notional) = Nominal * Forward | B37: =B21*B36 -> 9.0887906e+08
A38: PV (floating) = Amount * DF_settlement [discount curve = settlement curve here] | B38: =B37*B35 -> 8.7335064e+08
A39: dForward/dSpot = DF_notional/DF_settlement | B39: =B34/B35 -> 1.0098656
A40: FX delta = Nominal * dForward/dSpot * DF_settlement | B40: =B21*B39*B35 -> 970389.6
A42: Per-node curve-vertex derivatives (floating case)
A43: dRate/dNode_j (shared: same node grid for both curves) | B43: =IF(B16=B28,1-B29,IF(B16=C28,B29,0)) -> 0 | C43: =IF(C16=B28,1-B29,IF(C16=C28,B29,0)) -> 0 | D43: =IF(D16=B28,1-B29,IF(D16=C28,B29,0)) -> 0 | E43: =IF(E16=B28,1-B29,IF(E16=C28,B29,0)) -> 0 | F43: =IF(F16=B28,1-B29,IF(F16=C28,B29,0)) -> 0.99726027 | G43: =IF(G16=B28,1-B29,IF(G16=C28,B29,0)) -> 0.002739726
A44: dDF_notional/dNode_j = -(t_floating/360) * dRate/dNode_j / wf_notional^2 | B44: =-(B22/360)*B43/(B32^2) -> 0 | C44: =-(B22/360)*C43/(B32^2) -> 0 | D44: =-(B22/360)*D43/(B32^2) -> 0 | E44: =-(B22/360)*E43/(B32^2) -> 0 | F44: =-(B22/360)*F43/(B32^2) -> -0.95472737 | G44: =-(B22/360)*G43/(B32^2) -> -0.0026228774
A45: dDF_settlement/dNode_j = -(t_floating/360) * dRate/dNode_j / wf_settlement^2 | B45: =-(B22/360)*B43/(B33^2) -> 0 | C45: =-(B22/360)*C43/(B33^2) -> 0 | D45: =-(B22/360)*D43/(B33^2) -> 0 | E45: =-(B22/360)*E43/(B33^2) -> 0 | F45: =-(B22/360)*F43/(B33^2) -> -0.93616455 | G45: =-(B22/360)*G43/(B33^2) -> -0.0025718806
A46: dPV/dNotionalNode_j = Nominal * Spot * dDF_notional/dNode_j / DF_settlement * DF_settlement | B46: =B21*B20*B44/B35*B35 -> 0 | C46: =B21*B20*C44/B35*B35 -> 0 | D46: =B21*B20*D44/B35*B35 -> 0 | E46: =B21*B20*E44/B35*B35 -> 0 | F46: =B21*B20*F44/B35*B35 -> -8.5925463e+08 | G46: =B21*B20*G44/B35*B35 -> -2360589.7
A47: dPV/dCipSettlementNode_j = Nominal * (-Spot*DF_notional/DF_settlement^2) * dDF_settlement/dNode_j * DF_settlement | B47: =B21*(-B20*B34/(B35^2))*B45*B35 -> 0 | C47: =B21*(-B20*B34/(B35^2))*C45*B35 -> 0 | D47: =B21*(-B20*B34/(B35^2))*D45*B35 -> 0 | E47: =B21*(-B20*B34/(B35^2))*E45*B35 -> 0 | F47: =B21*(-B20*B34/(B35^2))*F45*B35 -> 8.5086036e+08 | G47: =B21*(-B20*B34/(B35^2))*G45*B35 -> 2337528.5
A48: dPV/dDiscountNode_j = Amount * dDF_settlement/dNode_j [discount curve = settlement curve] | B48: =B37*B45 -> 0 | C48: =B37*C45 -> 0 | D48: =B37*D45 -> 0 | E48: =B37*E45 -> 0 | F48: =B37*F45 -> -8.5086036e+08 | G48: =B37*G45 -> -2337528.5
...

Sheet Overnight
A1: OvernightIndexMultiCurrencyCashflow
A2: qcfinancial results (Python, live — see settlement_currency_review.py)
B3: Step | C3: Amount / PV (CLP) | D3: Notes
A4: Spot fixing (historical FX = 875.0) | B4: 875000000 | D4: settlement_amount() after ForwardFXRates.set_fx_rate
A5: CIP forward, still floating | B5: 8.7335064e+08 | D5: PresentValueFX.pv; FX delta = 970,389.6026
A6: CIP forward, already fixed | B6: 8.5966961e+08 | D6: PresentValueFX.pv; all curve/spot derivatives are 0 once fixed
A8: Floating-case curve-vertex derivatives at node 5 (t=365d):
A9: notional-curve | B9: -8.5925463e+08
A10: CIP-settlement-curve | B10: 8.5086036e+08
A11: discount-curve | B11: -8.5086036e+08
A16: Node t (days) | B16: =Curves!B2 -> 1 | C16: =Curves!C2 -> 30 | D16: =Curves!D2 -> 90 | E16: =Curves!E2 -> 180 | F16: =Curves!F2 -> 365 | G16: =Curves!G2 -> 730
A17: Notional curve rate | B17: =Curves!B3 -> 0.01 | C17: =Curves!C3 -> 0.015 | D17: =Curves!D3 -> 0.02 | E17: =Curves!E3 -> 0.025 | F17: =Curves!F3 -> 0.03 | G17: =Curves!G3 -> 0.035
A18: Settlement/discount curve rate | B18: =Curves!B4 -> 0.02 | C18: =Curves!C4 -> 0.025 | D18: =Curves!D4 -> 0.03 | E18: =Curves!E4 -> 0.035 | F18: =Curves!F4 -> 0.04 | G18: =Curves!G4 -> 0.045
A20: Spot | B20: =Curves!B6 -> 900
A21: Nominal (notional-currency amount(); zero-rate construction, see notebook) | B21: =Curves!B7 -> 1000000
A22: t_floating | B22: =Curves!B8 -> 366
A23: t_fixed | B23: =Curves!B9 -> 183
A24: Historical FX fixing | B24: =Curves!B10 -> 875
A26: CIP forward projection (still floating)
A27: idx (largest node <= t_floating) | B27: =MATCH(B22,Curves!$B$2:$G$2,1) -> 5
A28: x1, x2 (bracketing node t's) | B28: =INDEX(Curves!$B$2:$G$2,B27) -> 365 | C28: =IF(B27=6,B28,INDEX(Curves!$B$2:$G$2,B27+1)) -> 730
A29: frac = (t_floating - x1) / (x2 - x1) | B29: =IF(B27=6,0,(B22-B28)/(C28-B28)) -> 0.002739726
A30: Interpolated notional-curve rate at t_floating | B30: =INDEX(Curves!$B$3:$G$3,B27)+(INDEX(Curves!$B$3:$G$3,B27+1-IF(B27=6,1,0))-INDEX(Curves!$B$3:$G$3,B27))*B29 -> 0.030013699
A31: Interpolated settlement-curve rate at t_floating | B31: =INDEX(Curves!$B$4:$G$4,B27)+(INDEX(Curves!$B$4:$G$4,B27+1-IF(B27=6,1,0))-INDEX(Curves!$B$4:$G$4,B27))*B29 -> 0.040013699
A32: wf_notional = 1 + rate * t_floating/360 | B32: =1+B30*B22/360 -> 1.0305139
A33: wf_settlement = 1 + rate * t_floating/360 | B33: =1+B31*B22/360 -> 1.0406806
A34: DF_notional(t_floating) = 1/wf_notional | B34: =1/B32 -> 0.9703896
A35: DF_settlement(t_floating) = 1/wf_settlement | B35: =1/B33 -> 0.96090963
A36: Forward = Spot * DF_notional / DF_settlement | B36: =B20*B34/B35 -> 908.87906
A37: Amount (settlement ccy, strong-side notional) = Nominal * Forward | B37: =B21*B36 -> 9.0887906e+08
A38: PV (floating) = Amount * DF_settlement [discount curve = settlement curve here] | B38: =B37*B35 -> 8.7335064e+08
A39: dForward/dSpot = DF_notional/DF_settlement | B39: =B34/B35 -> 1.0098656
A40: FX delta = Nominal * dForward/dSpot * DF_settlement | B40: =B21*B39*B35 -> 970389.6
A42: Per-node curve-vertex derivatives (floating case)
A43: dRate/dNode_j (shared: same node grid for both curves) | B43: =IF(B16=B28,1-B29,IF(B16=C28,B29,0)) -> 0 | C43: =IF(C16=B28,1-B29,IF(C16=C28,B29,0)) -> 0 | D43: =IF(D16=B28,1-B29,IF(D16=C28,B29,0)) -> 0 | E43: =IF(E16=B28,1-B29,IF(E16=C28,B29,0)) -> 0 | F43: =IF(F16=B28,1-B29,IF(F16=C28,B29,0)) -> 0.99726027 | G43: =IF(G16=B28,1-B29,IF(G16=C28,B29,0)) -> 0.002739726
A44: dDF_notional/dNode_j = -(t_floating/360) * dRate/dNode_j / wf_notional^2 | B44: =-(B22/360)*B43/(B32^2) -> 0 | C44: =-(B22/360)*C43/(B32^2) -> 0 | D44: =-(B22/360)*D43/(B32^2) -> 0 | E44: =-(B22/360)*E43/(B32^2) -> 0 | F44: =-(B22/360)*F43/(B32^2) -> -0.95472737 | G44: =-(B22/360)*G43/(B32^2) -> -0.0026228774
A45: dDF_settlement/dNode_j = -(t_floating/360) * dRate/dNode_j / wf_settlement^2 | B45: =-(B22/360)*B43/(B33^2) -> 0 | C45: =-(B22/360)*C43/(B33^2) -> 0 | D45: =-(B22/360)*D43/(B33^2) -> 0 | E45: =-(B22/360)*E43/(B33^2) -> 0 | F45: =-(B22/360)*F43/(B33^2) -> -0.93616455 | G45: =-(B22/360)*G43/(B33^2) -> -0.0025718806
A46: dPV/dNotionalNode_j = Nominal * Spot * dDF_notional/dNode_j / DF_settlement * DF_settlement | B46: =B21*B20*B44/B35*B35 -> 0 | C46: =B21*B20*C44/B35*B35 -> 0 | D46: =B21*B20*D44/B35*B35 -> 0 | E46: =B21*B20*E44/B35*B35 -> 0 | F46: =B21*B20*F44/B35*B35 -> -8.5925463e+08 | G46: =B21*B20*G44/B35*B35 -> -2360589.7
A47: dPV/dCipSettlementNode_j = Nominal * (-Spot*DF_notional/DF_settlement^2) * dDF_settlement/dNode_j * DF_settlement | B47: =B21*(-B20*B34/(B35^2))*B45*B35 -> 0 | C47: =B21*(-B20*B34/(B35^2))*C45*B35 -> 0 | D47: =B21*(-B20*B34/(B35^2))*D45*B35 -> 0 | E47: =B21*(-B20*B34/(B35^2))*E45*B35 -> 0 | F47: =B21*(-B20*B34/(B35^2))*F45*B35 -> 8.5086036e+08 | G47: =B21*(-B20*B34/(B35^2))*G45*B35 -> 2337528.5
A48: dPV/dDiscountNode_j = Amount * dDF_settlement/dNode_j [discount curve = settlement curve] | B48: =B37*B45 -> 0 | C48: =B37*C45 -> 0 | D48: =B37*D45 -> 0 | E48: =B37*E45 -> 0 | F48: =B37*F45 -> -8.5086036e+08 | G48: =B37*G45 -> -2337528.5
...

Sheet CompOvernight
A1: CompoundedOvernightRateMultiCurrencyCashflow2
A2: qcfinancial results (Python, live — see settlement_currency_review.py)
B3: Step | C3: Amount / PV (CLP) | D3: Notes
A4: Spot fixing (historical FX = 875.0) | B4: 875000000 | D4: settlement_amount() after ForwardFXRates.set_fx_rate
A5: CIP forward, still floating | B5: 8.7335064e+08 | D5: PresentValueFX.pv; FX delta = 970,389.6026
A6: CIP forward, already fixed | B6: 8.5966961e+08 | D6: PresentValueFX.pv; all curve/spot derivatives are 0 once fixed
A8: Floating-case curve-vertex derivatives at node 5 (t=365d):
A9: notional-curve | B9: -8.5925463e+08
A10: CIP-settlement-curve | B10: 8.5086036e+08
A11: discount-curve | B11: -8.5086036e+08
A16: Node t (days) | B16: =Curves!B2 -> 1 | C16: =Curves!C2 -> 30 | D16: =Curves!D2 -> 90 | E16: =Curves!E2 -> 180 | F16: =Curves!F2 -> 365 | G16: =Curves!G2 -> 730
A17: Notional curve rate | B17: =Curves!B3 -> 0.01 | C17: =Curves!C3 -> 0.015 | D17: =Curves!D3 -> 0.02 | E17: =Curves!E3 -> 0.025 | F17: =Curves!F3 -> 0.03 | G17: =Curves!G3 -> 0.035
A18: Settlement/discount curve rate | B18: =Curves!B4 -> 0.02 | C18: =Curves!C4 -> 0.025 | D18: =Curves!D4 -> 0.03 | E18: =Curves!E4 -> 0.035 | F18: =Curves!F4 -> 0.04 | G18: =Curves!G4 -> 0.045
A20: Spot | B20: =Curves!B6 -> 900
A21: Nominal (notional-currency amount(); zero-rate construction, see notebook) | B21: =Curves!B7 -> 1000000
A22: t_floating | B22: =Curves!B8 -> 366
A23: t_fixed | B23: =Curves!B9 -> 183
A24: Historical FX fixing | B24: =Curves!B10 -> 875
A26: CIP forward projection (still floating)
A27: idx (largest node <= t_floating) | B27: =MATCH(B22,Curves!$B$2:$G$2,1) -> 5
A28: x1, x2 (bracketing node t's) | B28: =INDEX(Curves!$B$2:$G$2,B27) -> 365 | C28: =IF(B27=6,B28,INDEX(Curves!$B$2:$G$2,B27+1)) -> 730
A29: frac = (t_floating - x1) / (x2 - x1) | B29: =IF(B27=6,0,(B22-B28)/(C28-B28)) -> 0.002739726
A30: Interpolated notional-curve rate at t_floating | B30: =INDEX(Curves!$B$3:$G$3,B27)+(INDEX(Curves!$B$3:$G$3,B27+1-IF(B27=6,1,0))-INDEX(Curves!$B$3:$G$3,B27))*B29 -> 0.030013699
A31: Interpolated settlement-curve rate at t_floating | B31: =INDEX(Curves!$B$4:$G$4,B27)+(INDEX(Curves!$B$4:$G$4,B27+1-IF(B27=6,1,0))-INDEX(Curves!$B$4:$G$4,B27))*B29 -> 0.040013699
A32: wf_notional = 1 + rate * t_floating/360 | B32: =1+B30*B22/360 -> 1.0305139
A33: wf_settlement = 1 + rate * t_floating/360 | B33: =1+B31*B22/360 -> 1.0406806
A34: DF_notional(t_floating) = 1/wf_notional | B34: =1/B32 -> 0.9703896
A35: DF_settlement(t_floating) = 1/wf_settlement | B35: =1/B33 -> 0.96090963
A36: Forward = Spot * DF_notional / DF_settlement | B36: =B20*B34/B35 -> 908.87906
A37: Amount (settlement ccy, strong-side notional) = Nominal * Forward | B37: =B21*B36 -> 9.0887906e+08
A38: PV (floating) = Amount * DF_settlement [discount curve = settlement curve here] | B38: =B37*B35 -> 8.7335064e+08
A39: dForward/dSpot = DF_notional/DF_settlement | B39: =B34/B35 -> 1.0098656
A40: FX delta = Nominal * dForward/dSpot * DF_settlement | B40: =B21*B39*B35 -> 970389.6
A42: Per-node curve-vertex derivatives (floating case)
A43: dRate/dNode_j (shared: same node grid for both curves) | B43: =IF(B16=B28,1-B29,IF(B16=C28,B29,0)) -> 0 | C43: =IF(C16=B28,1-B29,IF(C16=C28,B29,0)) -> 0 | D43: =IF(D16=B28,1-B29,IF(D16=C28,B29,0)) -> 0 | E43: =IF(E16=B28,1-B29,IF(E16=C28,B29,0)) -> 0 | F43: =IF(F16=B28,1-B29,IF(F16=C28,B29,0)) -> 0.99726027 | G43: =IF(G16=B28,1-B29,IF(G16=C28,B29,0)) -> 0.002739726
A44: dDF_notional/dNode_j = -(t_floating/360) * dRate/dNode_j / wf_notional^2 | B44: =-(B22/360)*B43/(B32^2) -> 0 | C44: =-(B22/360)*C43/(B32^2) -> 0 | D44: =-(B22/360)*D43/(B32^2) -> 0 | E44: =-(B22/360)*E43/(B32^2) -> 0 | F44: =-(B22/360)*F43/(B32^2) -> -0.95472737 | G44: =-(B22/360)*G43/(B32^2) -> -0.0026228774
A45: dDF_settlement/dNode_j = -(t_floating/360) * dRate/dNode_j / wf_settlement^2 | B45: =-(B22/360)*B43/(B33^2) -> 0 | C45: =-(B22/360)*C43/(B33^2) -> 0 | D45: =-(B22/360)*D43/(B33^2) -> 0 | E45: =-(B22/360)*E43/(B33^2) -> 0 | F45: =-(B22/360)*F43/(B33^2) -> -0.93616455 | G45: =-(B22/360)*G43/(B33^2) -> -0.0025718806
A46: dPV/dNotionalNode_j = Nominal * Spot * dDF_notional/dNode_j / DF_settlement * DF_settlement | B46: =B21*B20*B44/B35*B35 -> 0 | C46: =B21*B20*C44/B35*B35 -> 0 | D46: =B21*B20*D44/B35*B35 -> 0 | E46: =B21*B20*E44/B35*B35 -> 0 | F46: =B21*B20*F44/B35*B35 -> -8.5925463e+08 | G46: =B21*B20*G44/B35*B35 -> -2360589.7
A47: dPV/dCipSettlementNode_j = Nominal * (-Spot*DF_notional/DF_settlement^2) * dDF_settlement/dNode_j * DF_settlement | B47: =B21*(-B20*B34/(B35^2))*B45*B35 -> 0 | C47: =B21*(-B20*B34/(B35^2))*C45*B35 -> 0 | D47: =B21*(-B20*B34/(B35^2))*D45*B35 -> 0 | E47: =B21*(-B20*B34/(B35^2))*E45*B35 -> 0 | F47: =B21*(-B20*B34/(B35^2))*F45*B35 -> 8.5086036e+08 | G47: =B21*(-B20*B34/(B35^2))*G45*B35 -> 2337528.5
A48: dPV/dDiscountNode_j = Amount * dDF_settlement/dNode_j [discount curve = settlement curve] | B48: =B37*B45 -> 0 | C48: =B37*C45 -> 0 | D48: =B37*D45 -> 0 | E48: =B37*E45 -> 0 | F48: =B37*F45 -> -8.5086036e+08 | G48: =B37*G45 -> -2337528.5
...

Sheet Simple_NDF
A1: SimpleMultiCurrencyCashflow
A2: qcfinancial results (Python, live — see settlement_currency_review.py)
B3: Step | C3: Amount / PV (CLP) | D3: Notes
A4: Spot fixing (historical FX = 875.0) | B4: 875000000 | D4: settlement_amount() after ForwardFXRates.set_fx_rate
A5: CIP forward, still floating | B5: 8.7335064e+08 | D5: PresentValueFX.pv; FX delta = 970,389.6026
A6: CIP forward, already fixed | B6: 8.5966961e+08 | D6: PresentValueFX.pv; all curve/spot derivatives are 0 once fixed
A8: Floating-case curve-vertex derivatives at node 5 (t=365d):
A9: notional-curve | B9: -8.5925463e+08
A10: CIP-settlement-curve | B10: 8.5086036e+08
A11: discount-curve | B11: -8.5086036e+08
A16: Node t (days) | B16: =Curves!B2 -> 1 | C16: =Curves!C2 -> 30 | D16: =Curves!D2 -> 90 | E16: =Curves!E2 -> 180 | F16: =Curves!F2 -> 365 | G16: =Curves!G2 -> 730
A17: Notional curve rate | B17: =Curves!B3 -> 0.01 | C17: =Curves!C3 -> 0.015 | D17: =Curves!D3 -> 0.02 | E17: =Curves!E3 -> 0.025 | F17: =Curves!F3 -> 0.03 | G17: =Curves!G3 -> 0.035
A18: Settlement/discount curve rate | B18: =Curves!B4 -> 0.02 | C18: =Curves!C4 -> 0.025 | D18: =Curves!D4 -> 0.03 | E18: =Curves!E4 -> 0.035 | F18: =Curves!F4 -> 0.04 | G18: =Curves!G4 -> 0.045
A20: Spot | B20: =Curves!B6 -> 900
A21: Nominal (notional-currency amount(); zero-rate construction, see notebook) | B21: =Curves!B7 -> 1000000
A22: t_floating | B22: =Curves!B8 -> 366
A23: t_fixed | B23: =Curves!B9 -> 183
A24: Historical FX fixing | B24: =Curves!B10 -> 875
A26: CIP forward projection (still floating)
A27: idx (largest node <= t_floating) | B27: =MATCH(B22,Curves!$B$2:$G$2,1) -> 5
A28: x1, x2 (bracketing node t's) | B28: =INDEX(Curves!$B$2:$G$2,B27) -> 365 | C28: =IF(B27=6,B28,INDEX(Curves!$B$2:$G$2,B27+1)) -> 730
A29: frac = (t_floating - x1) / (x2 - x1) | B29: =IF(B27=6,0,(B22-B28)/(C28-B28)) -> 0.002739726
A30: Interpolated notional-curve rate at t_floating | B30: =INDEX(Curves!$B$3:$G$3,B27)+(INDEX(Curves!$B$3:$G$3,B27+1-IF(B27=6,1,0))-INDEX(Curves!$B$3:$G$3,B27))*B29 -> 0.030013699
A31: Interpolated settlement-curve rate at t_floating | B31: =INDEX(Curves!$B$4:$G$4,B27)+(INDEX(Curves!$B$4:$G$4,B27+1-IF(B27=6,1,0))-INDEX(Curves!$B$4:$G$4,B27))*B29 -> 0.040013699
A32: wf_notional = 1 + rate * t_floating/360 | B32: =1+B30*B22/360 -> 1.0305139
A33: wf_settlement = 1 + rate * t_floating/360 | B33: =1+B31*B22/360 -> 1.0406806
A34: DF_notional(t_floating) = 1/wf_notional | B34: =1/B32 -> 0.9703896
A35: DF_settlement(t_floating) = 1/wf_settlement | B35: =1/B33 -> 0.96090963
A36: Forward = Spot * DF_notional / DF_settlement | B36: =B20*B34/B35 -> 908.87906
A37: Amount (settlement ccy, strong-side notional) = Nominal * Forward | B37: =B21*B36 -> 9.0887906e+08
A38: PV (floating) = Amount * DF_settlement [discount curve = settlement curve here] | B38: =B37*B35 -> 8.7335064e+08
A39: dForward/dSpot = DF_notional/DF_settlement | B39: =B34/B35 -> 1.0098656
A40: FX delta = Nominal * dForward/dSpot * DF_settlement | B40: =B21*B39*B35 -> 970389.6
A42: Per-node curve-vertex derivatives (floating case)
A43: dRate/dNode_j (shared: same node grid for both curves) | B43: =IF(B16=B28,1-B29,IF(B16=C28,B29,0)) -> 0 | C43: =IF(C16=B28,1-B29,IF(C16=C28,B29,0)) -> 0 | D43: =IF(D16=B28,1-B29,IF(D16=C28,B29,0)) -> 0 | E43: =IF(E16=B28,1-B29,IF(E16=C28,B29,0)) -> 0 | F43: =IF(F16=B28,1-B29,IF(F16=C28,B29,0)) -> 0.99726027 | G43: =IF(G16=B28,1-B29,IF(G16=C28,B29,0)) -> 0.002739726
A44: dDF_notional/dNode_j = -(t_floating/360) * dRate/dNode_j / wf_notional^2 | B44: =-(B22/360)*B43/(B32^2) -> 0 | C44: =-(B22/360)*C43/(B32^2) -> 0 | D44: =-(B22/360)*D43/(B32^2) -> 0 | E44: =-(B22/360)*E43/(B32^2) -> 0 | F44: =-(B22/360)*F43/(B32^2) -> -0.95472737 | G44: =-(B22/360)*G43/(B32^2) -> -0.0026228774
A45: dDF_settlement/dNode_j = -(t_floating/360) * dRate/dNode_j / wf_settlement^2 | B45: =-(B22/360)*B43/(B33^2) -> 0 | C45: =-(B22/360)*C43/(B33^2) -> 0 | D45: =-(B22/360)*D43/(B33^2) -> 0 | E45: =-(B22/360)*E43/(B33^2) -> 0 | F45: =-(B22/360)*F43/(B33^2) -> -0.93616455 | G45: =-(B22/360)*G43/(B33^2) -> -0.0025718806
A46: dPV/dNotionalNode_j = Nominal * Spot * dDF_notional/dNode_j / DF_settlement * DF_settlement | B46: =B21*B20*B44/B35*B35 -> 0 | C46: =B21*B20*C44/B35*B35 -> 0 | D46: =B21*B20*D44/B35*B35 -> 0 | E46: =B21*B20*E44/B35*B35 -> 0 | F46: =B21*B20*F44/B35*B35 -> -8.5925463e+08 | G46: =B21*B20*G44/B35*B35 -> -2360589.7
A47: dPV/dCipSettlementNode_j = Nominal * (-Spot*DF_notional/DF_settlement^2) * dDF_settlement/dNode_j * DF_settlement | B47: =B21*(-B20*B34/(B35^2))*B45*B35 -> 0 | C47: =B21*(-B20*B34/(B35^2))*C45*B35 -> 0 | D47: =B21*(-B20*B34/(B35^2))*D45*B35 -> 0 | E47: =B21*(-B20*B34/(B35^2))*E45*B35 -> 0 | F47: =B21*(-B20*B34/(B35^2))*F45*B35 -> 8.5086036e+08 | G47: =B21*(-B20*B34/(B35^2))*G45*B35 -> 2337528.5
A48: dPV/dDiscountNode_j = Amount * dDF_settlement/dNode_j [discount curve = settlement curve] | B48: =B37*B45 -> 0 | C48: =B37*C45 -> 0 | D48: =B37*D45 -> 0 | E48: =B37*E45 -> 0 | F48: =B37*F45 -> -8.5086036e+08 | G48: =B37*G45 -> -2337528.5
...
